<?xml version="1.0">
<robot name="giraffe_robot">
    <material name="grey">
        <color rgba="0.5 0.5 0.5 1"/>
    </material>
    <material name="blue">
        <color rgba="0.0 0.0 0.8 1"/>
    </material>
    <material name="red">
        <color rgba="0.8 0.0 0.0 1"/>
    </material>

    <link name="world" />

    <joint name="giraffe_fixed_base" type="fixed">
        <parent link="world" />
        <child  link="base_link" />
        <origin xyz="0 0 4.0" rpy="0 0 0" />
    </joint>

    <link name="base_link">
        <visual>
            <material name="grey" />
            <geometry>
                <box size="0.2 0.2 0.1"/>
            </geometry>
        </visual>

        <inertial>
            <mass value="1.0" />
            <inertia ixx="0.01" ixy="0" ixz="0" iyy="0.01" iyz="0" izz="0.01"/>
        </inertial>
    </link>

    <joint name="joint1_pan" type="revolute">
        <parent link="base_link" />
        <child  link="link1_shoulder" />
        <origin xyz="0 0 0" rpy="0 0 0" />
        <axis xyz="0 0 1" />
        <limit lower="-3.14" upper="3.14" effort="100" velocity="1.0"/>
    </joint>

    <link name="link1_shoulder">
        <visual>
            <material name="blue" />
            <geometry>
                <sphere radius="0.1" />
            </geometry>
        </visual>

        <inertial>
            <mass value="0.5" />
            <inertia ixx="0.01" ixy="0" ixz="0" iyy="0.01" iyz="0" izz="0.01"/>
        </inertial>
    </link>

    <joint name="joint2_tilt" type="revolute">
        <parent link="link1_shoulder"/>
        <child link="link2_tube_outer"/>
        <origin xyz="0 0 0" rpy="0 1.57 0"/>
        <axis xyz="0 1 0"/>
        <limit lower="-1.57" upper="0.0" effort="100" velocity="1.0"/>
    </joint>

    <link name="link2_tube_outer">
        <visual>
        <origin xyz="0 0 0.25" rpy="0 0 0"/>
        <geometry>
            <cylinder radius="0.05" length="0.5"/>
        </geometry>
        <material name="grey"/>
        </visual>
        <inertial>
            <mass value="2.0"/>
            <inertia ixx="0.1" ixy="0" ixz="0" iyy="0.1" iyz="0" izz="0.01"/>
        </inertial>
    </link>

    <joint name="joint3_prismatic" type="prismatic">
        <parent link="link2_tube_outer"/>
        <child link="link3_tube_inner"/>
        <origin xyz="0 0 0.5" rpy="0 0 0"/>
        <axis xyz="0 0 1"/>
        <limit lower="0.0" upper="7.0" effort="200" velocity="2"/>
    </joint>

    <link name="link3_tube_inner">
        <visual>
        <origin xyz="0 0 -0.25" rpy="0 0 0"/>
        <geometry>
            <cylinder radius="0.03" length="0.5"/>
        </geometry>
        <material name="blue"/>
        </visual>
        <inertial>
        <mass value="1.0"/>
        <inertia ixx="0.05" ixy="0" ixz="0" iyy="0.05" iyz="0" izz="0.005"/>
        </inertial>
    </link>

    <joint name="joint4_pitch" type="revolute">
        <parent link="link3_tube_inner"/>
        <child link="link4_wrist"/>
        <origin xyz="0 0 0" rpy="0 0 0"/>
        <axis xyz="0 1 0"/>
        <limit lower="-1.57" upper="1.57" effort="50" velocity="2.0"/>
    </joint>

    <link name="link4_wrist">
        <visual>
            <origin xyz="0 0 0.1" rpy="0 0 0"/>
            <geometry>
                <cylinder radius="0.02" length="0.2"/>
            </geometry>
            <material name="red"/>
        </visual>
        <inertial>
        <mass value="0.2"/>
        <inertia ixx="0.001" ixy="0" ixz="0" iyy="0.001" iyz="0" izz="0.001"/>
        </inertial>
    </link>

    <joint name="joint5_roll" type="revolute">
        <parent link="link4_wrist"/>
        <child link="end_effector"/>
        <origin xyz="0 0 0.2" rpy="0 0 0"/>
        <axis xyz="1 0 0"/>
        <limit lower="-3.14" upper="3.14" effort="50" velocity="2.0"/>
    </joint>

    <link name="end_effector">
        <visual>
            <origin xyz="0 0 0.05" rpy="0 0 0"/>
            <geometry>
                <cylinder radius="0.01" length="0.1"/>
            </geometry>
            <material name="grey"/>
        </visual>
        <visual>
            <origin xyz="0 0 0.1" rpy="0.707 0 0"/> 
            <geometry>
                <mesh filename="package://giraffe_robot/models/microphone.stl" scale="0.001 0.001 0.001"/>
            </geometry>
            <material name="blue"/>
        </visual>
        <inertial>
            <mass value="0.2"/>
            <inertia ixx="0.001" ixy="0" ixz="0" iyy="0.001" iyz="0" izz="0.001"/>
        </inertial>
    </link>
</robot> 
